2023-04-05 22:03:07,982 INFO    StreamThr :35292 [internal.py:wandb_internal():87] W&B internal server running at pid: 35292, started at: 2023-04-05 22:03:07.981942
2023-04-05 22:03:07,984 DEBUG   HandlerThread:35292 [handler.py:handle_request():144] handle_request: status
2023-04-05 22:03:07,985 INFO    WriterThread:35292 [datastore.py:open_for_write():85] open: D:\Projects\PFedTrans\system\wandb\run-20230405_220307-yaze6r8c\run-yaze6r8c.wandb
2023-04-05 22:03:07,988 DEBUG   SenderThread:35292 [sender.py:send():336] send: header
2023-04-05 22:03:07,988 DEBUG   SenderThread:35292 [sender.py:send():336] send: run
2023-04-05 22:03:09,198 INFO    SenderThread:35292 [dir_watcher.py:__init__():216] watching files in: D:\Projects\PFedTrans\system\wandb\run-20230405_220307-yaze6r8c\files
2023-04-05 22:03:09,200 INFO    SenderThread:35292 [sender.py:_start_run_threads():1067] run started: yaze6r8c with start time 1680703387.984139
2023-04-05 22:03:09,200 DEBUG   SenderThread:35292 [sender.py:send_request():363] send_request: summary_record
2023-04-05 22:03:09,200 INFO    SenderThread:35292 [sender.py:_save_file():1321] saving file wandb-summary.json with policy end
2023-04-05 22:03:09,200 DEBUG   HandlerThread:35292 [handler.py:handle_request():144] handle_request: check_version
2023-04-05 22:03:09,201 DEBUG   SenderThread:35292 [sender.py:send_request():363] send_request: check_version
2023-04-05 22:03:09,218 DEBUG   HandlerThread:35292 [handler.py:handle_request():144] handle_request: run_start
2023-04-05 22:03:09,261 DEBUG   HandlerThread:35292 [system_info.py:__init__():31] System info init
2023-04-05 22:03:09,262 DEBUG   HandlerThread:35292 [system_info.py:__init__():46] System info init done
2023-04-05 22:03:09,262 INFO    HandlerThread:35292 [system_monitor.py:start():151] Starting system monitor
2023-04-05 22:03:09,262 INFO    SystemMonitor:35292 [system_monitor.py:_start():116] Starting system asset monitoring threads
2023-04-05 22:03:09,262 INFO    HandlerThread:35292 [system_monitor.py:probe():172] Collecting system info
2023-04-05 22:03:09,269 INFO    SystemMonitor:35292 [interfaces.py:start():168] Started cpu
2023-04-05 22:03:09,269 INFO    SystemMonitor:35292 [interfaces.py:start():168] Started disk
2023-04-05 22:03:09,271 INFO    SystemMonitor:35292 [interfaces.py:start():168] Started gpu
2023-04-05 22:03:09,281 INFO    SystemMonitor:35292 [interfaces.py:start():168] Started memory
2023-04-05 22:03:09,308 INFO    SystemMonitor:35292 [interfaces.py:start():168] Started network
2023-04-05 22:03:09,321 DEBUG   HandlerThread:35292 [system_info.py:probe():195] Probing system
2023-04-05 22:03:09,321 DEBUG   HandlerThread:35292 [system_info.py:probe():241] Probing system done
2023-04-05 22:03:09,321 DEBUG   HandlerThread:35292 [system_monitor.py:probe():181] {'os': 'Windows-10-10.0.22000-SP0', 'python': '3.8.11', 'heartbeatAt': '2023-04-05T14:03:09.321201', 'startedAt': '2023-04-05T14:03:07.969428', 'docker': None, 'cuda': None, 'args': ('-data', 'Cifar10', '-lbs', '16', '-jr', '1', '-nb', '100', '-m', 'dnn', '-algo', 'PerAvg', '-gr', '1000', '-did', '0', '-go', 'dnn', '-bt', '0.001', '-nc', '20', '-ere', '1', '-wandb', 'True'), 'state': 'running', 'program': 'main.py', 'codePath': 'main.py', 'host': 'DESKTOP-HSUG78F', 'username': 'MSI', 'executable': 'C:\\Users\\MSI\\miniconda3\\envs\\d2l\\python.exe', 'cpu_count': 12, 'cpu_count_logical': 24, 'cpu_freq': {'current': 3701.0, 'min': 0.0, 'max': 3701.0}, 'cpu_freq_per_core': [{'current': 3701.0, 'min': 0.0, 'max': 3701.0}], 'disk': {'total': 347.65429306030273, 'used': 152.22686767578125}, 'gpu': 'NVIDIA GeForce RTX 3080 Ti', 'gpu_count': 1, 'gpu_devices': [{'name': 'NVIDIA GeForce RTX 3080 Ti', 'memory_total': 12884901888}], 'memory': {'total': 31.927108764648438}}
2023-04-05 22:03:09,321 INFO    HandlerThread:35292 [system_monitor.py:probe():182] Finished collecting system info
2023-04-05 22:03:09,321 INFO    HandlerThread:35292 [system_monitor.py:probe():185] Publishing system info
2023-04-05 22:03:09,321 DEBUG   HandlerThread:35292 [system_info.py:_save_pip():51] Saving list of pip packages installed into the current environment
2023-04-05 22:03:09,322 DEBUG   HandlerThread:35292 [system_info.py:_save_pip():67] Saving pip packages done
2023-04-05 22:03:09,322 DEBUG   HandlerThread:35292 [system_info.py:_save_conda():74] Saving list of conda packages installed into the current environment
2023-04-05 22:03:09,332 ERROR   HandlerThread:35292 [system_info.py:_save_conda():85] Error saving conda packages: [WinError 2] 系统找不到指定的文件。
Traceback (most recent call last):
  File "C:\Users\MSI\miniconda3\envs\d2l\lib\site-packages\wandb\sdk\internal\system\system_info.py", line 81, in _save_conda
    subprocess.call(
  File "C:\Users\MSI\miniconda3\envs\d2l\lib\subprocess.py", line 340, in call
    with Popen(*popenargs, **kwargs) as p:
  File "C:\Users\MSI\miniconda3\envs\d2l\lib\subprocess.py", line 858, in __init__
    self._execute_child(args, executable, preexec_fn, close_fds,
  File "C:\Users\MSI\miniconda3\envs\d2l\lib\subprocess.py", line 1311, in _execute_child
    hp, ht, pid, tid = _winapi.CreateProcess(executable, args,
FileNotFoundError: [WinError 2] 系统找不到指定的文件。
2023-04-05 22:03:09,335 DEBUG   HandlerThread:35292 [system_info.py:_save_conda():86] Saving conda packages done
2023-04-05 22:03:09,336 INFO    HandlerThread:35292 [system_monitor.py:probe():187] Finished publishing system info
2023-04-05 22:03:09,351 DEBUG   SenderThread:35292 [sender.py:send():336] send: files
2023-04-05 22:03:09,351 INFO    SenderThread:35292 [sender.py:_save_file():1321] saving file wandb-metadata.json with policy now
2023-04-05 22:03:09,365 DEBUG   HandlerThread:35292 [handler.py:handle_request():144] handle_request: stop_status
2023-04-05 22:03:09,365 DEBUG   SenderThread:35292 [sender.py:send_request():363] send_request: stop_status
2023-04-05 22:03:09,968 DEBUG   SenderThread:35292 [sender.py:send():336] send: telemetry
2023-04-05 22:03:10,006 ERROR   wandb-upload_0:35292 [internal_api.py:upload_file():2004] upload_file exception https://storage.googleapis.com/wandb-production.appspot.com/gerid/fedtrans_exp/yaze6r8c/wandb-metadata.json?Expires=1680789789&GoogleAccessId=wandb-production%40appspot.gserviceaccount.com&Signature=BEedncaVomZ5Ufc466jFWDJw9qSr0JGLnX17KARu9PmsraH72jepv6CwMpkW12GtezNux%2BzRLxshycUnNmo6gdWg7jtnf%2BaMu9Ng3zfSkRMqdLfltBMEak71t90u2%2BGjp6i9hlKks6JF3jmM2jyUWce1Ux%2BvQ%2FKvPcPgXr7zUa1RTrtQU6JYSpCwSPxGecgslAAN30fkn2GDfC6VT%2B9VTe7xkY8k4wTk7dq1ztoaqRJO23ZksffAA2PuuoyLdpEwbs16RF0eS%2F6GNpl29UbIlMy3xi6X0sT%2FZQRNmBcl7tEUrCYqnAyqbB7Vn2P%2FTXZjrRRjDomHGt8aUNPjMa142A%3D%3D: HTTPSConnectionPool(host='storage.googleapis.com', port=443): Max retries exceeded with url: /wandb-production.appspot.com/gerid/fedtrans_exp/yaze6r8c/wandb-metadata.json?Expires=1680789789&GoogleAccessId=wandb-production%40appspot.gserviceaccount.com&Signature=BEedncaVomZ5Ufc466jFWDJw9qSr0JGLnX17KARu9PmsraH72jepv6CwMpkW12GtezNux%2BzRLxshycUnNmo6gdWg7jtnf%2BaMu9Ng3zfSkRMqdLfltBMEak71t90u2%2BGjp6i9hlKks6JF3jmM2jyUWce1Ux%2BvQ%2FKvPcPgXr7zUa1RTrtQU6JYSpCwSPxGecgslAAN30fkn2GDfC6VT%2B9VTe7xkY8k4wTk7dq1ztoaqRJO23ZksffAA2PuuoyLdpEwbs16RF0eS%2F6GNpl29UbIlMy3xi6X0sT%2FZQRNmBcl7tEUrCYqnAyqbB7Vn2P%2FTXZjrRRjDomHGt8aUNPjMa142A%3D%3D (Caused by SSLError(SSLEOFError(8, 'EOF occurred in violation of protocol (_ssl.c:1131)')))
2023-04-05 22:03:10,006 ERROR   wandb-upload_0:35292 [internal_api.py:upload_file():2006] upload_file request headers: {'User-Agent': 'python-requests/2.28.2', 'Accept-Encoding': 'gzip, deflate, br', 'Accept': '*/*', 'Connection': 'keep-alive', 'Content-Length': '1525'}
2023-04-05 22:03:10,007 ERROR   wandb-upload_0:35292 [internal_api.py:upload_file():2008] upload_file response body: 
2023-04-05 22:03:10,205 INFO    Thread-13 :35292 [dir_watcher.py:_on_file_created():275] file/dir created: D:\Projects\PFedTrans\system\wandb\run-20230405_220307-yaze6r8c\files\wandb-summary.json
2023-04-05 22:03:10,205 INFO    Thread-13 :35292 [dir_watcher.py:_on_file_created():275] file/dir created: D:\Projects\PFedTrans\system\wandb\run-20230405_220307-yaze6r8c\files\wandb-metadata.json
2023-04-05 22:03:10,205 INFO    Thread-13 :35292 [dir_watcher.py:_on_file_created():275] file/dir created: D:\Projects\PFedTrans\system\wandb\run-20230405_220307-yaze6r8c\files\output.log
2023-04-05 22:03:10,206 INFO    Thread-13 :35292 [dir_watcher.py:_on_file_created():275] file/dir created: D:\Projects\PFedTrans\system\wandb\run-20230405_220307-yaze6r8c\files\conda-environment.yaml
2023-04-05 22:03:10,206 INFO    Thread-13 :35292 [dir_watcher.py:_on_file_created():275] file/dir created: D:\Projects\PFedTrans\system\wandb\run-20230405_220307-yaze6r8c\files\requirements.txt
2023-04-05 22:03:11,208 ERROR   wandb-upload_0:35292 [internal_api.py:upload_file():2004] upload_file exception https://storage.googleapis.com/wandb-production.appspot.com/gerid/fedtrans_exp/yaze6r8c/wandb-metadata.json?Expires=1680789789&GoogleAccessId=wandb-production%40appspot.gserviceaccount.com&Signature=BEedncaVomZ5Ufc466jFWDJw9qSr0JGLnX17KARu9PmsraH72jepv6CwMpkW12GtezNux%2BzRLxshycUnNmo6gdWg7jtnf%2BaMu9Ng3zfSkRMqdLfltBMEak71t90u2%2BGjp6i9hlKks6JF3jmM2jyUWce1Ux%2BvQ%2FKvPcPgXr7zUa1RTrtQU6JYSpCwSPxGecgslAAN30fkn2GDfC6VT%2B9VTe7xkY8k4wTk7dq1ztoaqRJO23ZksffAA2PuuoyLdpEwbs16RF0eS%2F6GNpl29UbIlMy3xi6X0sT%2FZQRNmBcl7tEUrCYqnAyqbB7Vn2P%2FTXZjrRRjDomHGt8aUNPjMa142A%3D%3D: HTTPSConnectionPool(host='storage.googleapis.com', port=443): Max retries exceeded with url: /wandb-production.appspot.com/gerid/fedtrans_exp/yaze6r8c/wandb-metadata.json?Expires=1680789789&GoogleAccessId=wandb-production%40appspot.gserviceaccount.com&Signature=BEedncaVomZ5Ufc466jFWDJw9qSr0JGLnX17KARu9PmsraH72jepv6CwMpkW12GtezNux%2BzRLxshycUnNmo6gdWg7jtnf%2BaMu9Ng3zfSkRMqdLfltBMEak71t90u2%2BGjp6i9hlKks6JF3jmM2jyUWce1Ux%2BvQ%2FKvPcPgXr7zUa1RTrtQU6JYSpCwSPxGecgslAAN30fkn2GDfC6VT%2B9VTe7xkY8k4wTk7dq1ztoaqRJO23ZksffAA2PuuoyLdpEwbs16RF0eS%2F6GNpl29UbIlMy3xi6X0sT%2FZQRNmBcl7tEUrCYqnAyqbB7Vn2P%2FTXZjrRRjDomHGt8aUNPjMa142A%3D%3D (Caused by SSLError(SSLEOFError(8, 'EOF occurred in violation of protocol (_ssl.c:1131)')))
2023-04-05 22:03:11,208 ERROR   wandb-upload_0:35292 [internal_api.py:upload_file():2006] upload_file request headers: {'User-Agent': 'python-requests/2.28.2', 'Accept-Encoding': 'gzip, deflate, br', 'Accept': '*/*', 'Connection': 'keep-alive', 'Content-Length': '1525'}
2023-04-05 22:03:11,208 ERROR   wandb-upload_0:35292 [internal_api.py:upload_file():2008] upload_file response body: 
2023-04-05 22:03:12,217 INFO    Thread-13 :35292 [dir_watcher.py:_on_file_modified():292] file/dir modified: D:\Projects\PFedTrans\system\wandb\run-20230405_220307-yaze6r8c\files\output.log
2023-04-05 22:03:12,959 DEBUG   HandlerThread:35292 [handler.py:handle_request():144] handle_request: partial_history
2023-04-05 22:03:12,960 DEBUG   SenderThread:35292 [sender.py:send():336] send: history
2023-04-05 22:03:12,960 DEBUG   SenderThread:35292 [sender.py:send_request():363] send_request: summary_record
2023-04-05 22:03:12,961 INFO    SenderThread:35292 [sender.py:_save_file():1321] saving file wandb-summary.json with policy end
2023-04-05 22:03:13,230 INFO    Thread-13 :35292 [dir_watcher.py:_on_file_modified():292] file/dir modified: D:\Projects\PFedTrans\system\wandb\run-20230405_220307-yaze6r8c\files\wandb-summary.json
2023-04-05 22:03:13,362 ERROR   wandb-upload_0:35292 [internal_api.py:upload_file():2004] upload_file exception https://storage.googleapis.com/wandb-production.appspot.com/gerid/fedtrans_exp/yaze6r8c/wandb-metadata.json?Expires=1680789789&GoogleAccessId=wandb-production%40appspot.gserviceaccount.com&Signature=BEedncaVomZ5Ufc466jFWDJw9qSr0JGLnX17KARu9PmsraH72jepv6CwMpkW12GtezNux%2BzRLxshycUnNmo6gdWg7jtnf%2BaMu9Ng3zfSkRMqdLfltBMEak71t90u2%2BGjp6i9hlKks6JF3jmM2jyUWce1Ux%2BvQ%2FKvPcPgXr7zUa1RTrtQU6JYSpCwSPxGecgslAAN30fkn2GDfC6VT%2B9VTe7xkY8k4wTk7dq1ztoaqRJO23ZksffAA2PuuoyLdpEwbs16RF0eS%2F6GNpl29UbIlMy3xi6X0sT%2FZQRNmBcl7tEUrCYqnAyqbB7Vn2P%2FTXZjrRRjDomHGt8aUNPjMa142A%3D%3D: HTTPSConnectionPool(host='storage.googleapis.com', port=443): Max retries exceeded with url: /wandb-production.appspot.com/gerid/fedtrans_exp/yaze6r8c/wandb-metadata.json?Expires=1680789789&GoogleAccessId=wandb-production%40appspot.gserviceaccount.com&Signature=BEedncaVomZ5Ufc466jFWDJw9qSr0JGLnX17KARu9PmsraH72jepv6CwMpkW12GtezNux%2BzRLxshycUnNmo6gdWg7jtnf%2BaMu9Ng3zfSkRMqdLfltBMEak71t90u2%2BGjp6i9hlKks6JF3jmM2jyUWce1Ux%2BvQ%2FKvPcPgXr7zUa1RTrtQU6JYSpCwSPxGecgslAAN30fkn2GDfC6VT%2B9VTe7xkY8k4wTk7dq1ztoaqRJO23ZksffAA2PuuoyLdpEwbs16RF0eS%2F6GNpl29UbIlMy3xi6X0sT%2FZQRNmBcl7tEUrCYqnAyqbB7Vn2P%2FTXZjrRRjDomHGt8aUNPjMa142A%3D%3D (Caused by SSLError(SSLEOFError(8, 'EOF occurred in violation of protocol (_ssl.c:1131)')))
2023-04-05 22:03:13,362 ERROR   wandb-upload_0:35292 [internal_api.py:upload_file():2006] upload_file request headers: {'User-Agent': 'python-requests/2.28.2', 'Accept-Encoding': 'gzip, deflate, br', 'Accept': '*/*', 'Connection': 'keep-alive', 'Content-Length': '1525'}
2023-04-05 22:03:13,362 ERROR   wandb-upload_0:35292 [internal_api.py:upload_file():2008] upload_file response body: 
2023-04-05 22:03:13,362 INFO    wandb-upload_0:35292 [retry.py:__call__():172] Retry attempt failed:
Traceback (most recent call last):
  File "C:\Users\MSI\miniconda3\envs\d2l\lib\site-packages\urllib3\connectionpool.py", line 700, in urlopen
    self._prepare_proxy(conn)
  File "C:\Users\MSI\miniconda3\envs\d2l\lib\site-packages\urllib3\connectionpool.py", line 996, in _prepare_proxy
    conn.connect()
  File "C:\Users\MSI\miniconda3\envs\d2l\lib\site-packages\urllib3\connection.py", line 364, in connect
    self.sock = conn = self._connect_tls_proxy(hostname, conn)
  File "C:\Users\MSI\miniconda3\envs\d2l\lib\site-packages\urllib3\connection.py", line 499, in _connect_tls_proxy
    socket = ssl_wrap_socket(
  File "C:\Users\MSI\miniconda3\envs\d2l\lib\site-packages\urllib3\util\ssl_.py", line 453, in ssl_wrap_socket
    ssl_sock = _ssl_wrap_socket_impl(sock, context, tls_in_tls)
  File "C:\Users\MSI\miniconda3\envs\d2l\lib\site-packages\urllib3\util\ssl_.py", line 495, in _ssl_wrap_socket_impl
    return ssl_context.wrap_socket(sock)
  File "C:\Users\MSI\miniconda3\envs\d2l\lib\ssl.py", line 500, in wrap_socket
    return self.sslsocket_class._create(
  File "C:\Users\MSI\miniconda3\envs\d2l\lib\ssl.py", line 1040, in _create
    self.do_handshake()
  File "C:\Users\MSI\miniconda3\envs\d2l\lib\ssl.py", line 1309, in do_handshake
    self._sslobj.do_handshake()
ssl.SSLEOFError: EOF occurred in violation of protocol (_ssl.c:1131)

During handling of the above exception, another exception occurred:

Traceback (most recent call last):
  File "C:\Users\MSI\miniconda3\envs\d2l\lib\site-packages\requests\adapters.py", line 489, in send
    resp = conn.urlopen(
  File "C:\Users\MSI\miniconda3\envs\d2l\lib\site-packages\urllib3\connectionpool.py", line 787, in urlopen
    retries = retries.increment(
  File "C:\Users\MSI\miniconda3\envs\d2l\lib\site-packages\urllib3\util\retry.py", line 592, in increment
    raise MaxRetryError(_pool, url, error or ResponseError(cause))
urllib3.exceptions.MaxRetryError: HTTPSConnectionPool(host='storage.googleapis.com', port=443): Max retries exceeded with url: /wandb-production.appspot.com/gerid/fedtrans_exp/yaze6r8c/wandb-metadata.json?Expires=1680789789&GoogleAccessId=wandb-production%40appspot.gserviceaccount.com&Signature=BEedncaVomZ5Ufc466jFWDJw9qSr0JGLnX17KARu9PmsraH72jepv6CwMpkW12GtezNux%2BzRLxshycUnNmo6gdWg7jtnf%2BaMu9Ng3zfSkRMqdLfltBMEak71t90u2%2BGjp6i9hlKks6JF3jmM2jyUWce1Ux%2BvQ%2FKvPcPgXr7zUa1RTrtQU6JYSpCwSPxGecgslAAN30fkn2GDfC6VT%2B9VTe7xkY8k4wTk7dq1ztoaqRJO23ZksffAA2PuuoyLdpEwbs16RF0eS%2F6GNpl29UbIlMy3xi6X0sT%2FZQRNmBcl7tEUrCYqnAyqbB7Vn2P%2FTXZjrRRjDomHGt8aUNPjMa142A%3D%3D (Caused by SSLError(SSLEOFError(8, 'EOF occurred in violation of protocol (_ssl.c:1131)')))

During handling of the above exception, another exception occurred:

Traceback (most recent call last):
  File "C:\Users\MSI\miniconda3\envs\d2l\lib\site-packages\wandb\sdk\internal\internal_api.py", line 1999, in upload_file
    response = self._upload_file_session.put(
  File "C:\Users\MSI\miniconda3\envs\d2l\lib\site-packages\requests\sessions.py", line 647, in put
    return self.request("PUT", url, data=data, **kwargs)
  File "C:\Users\MSI\miniconda3\envs\d2l\lib\site-packages\requests\sessions.py", line 587, in request
    resp = self.send(prep, **send_kwargs)
  File "C:\Users\MSI\miniconda3\envs\d2l\lib\site-packages\requests\sessions.py", line 701, in send
    r = adapter.send(request, **kwargs)
  File "C:\Users\MSI\miniconda3\envs\d2l\lib\site-packages\requests\adapters.py", line 563, in send
    raise SSLError(e, request=request)
requests.exceptions.SSLError: HTTPSConnectionPool(host='storage.googleapis.com', port=443): Max retries exceeded with url: /wandb-production.appspot.com/gerid/fedtrans_exp/yaze6r8c/wandb-metadata.json?Expires=1680789789&GoogleAccessId=wandb-production%40appspot.gserviceaccount.com&Signature=BEedncaVomZ5Ufc466jFWDJw9qSr0JGLnX17KARu9PmsraH72jepv6CwMpkW12GtezNux%2BzRLxshycUnNmo6gdWg7jtnf%2BaMu9Ng3zfSkRMqdLfltBMEak71t90u2%2BGjp6i9hlKks6JF3jmM2jyUWce1Ux%2BvQ%2FKvPcPgXr7zUa1RTrtQU6JYSpCwSPxGecgslAAN30fkn2GDfC6VT%2B9VTe7xkY8k4wTk7dq1ztoaqRJO23ZksffAA2PuuoyLdpEwbs16RF0eS%2F6GNpl29UbIlMy3xi6X0sT%2FZQRNmBcl7tEUrCYqnAyqbB7Vn2P%2FTXZjrRRjDomHGt8aUNPjMa142A%3D%3D (Caused by SSLError(SSLEOFError(8, 'EOF occurred in violation of protocol (_ssl.c:1131)')))

During handling of the above exception, another exception occurred:

Traceback (most recent call last):
  File "C:\Users\MSI\miniconda3\envs\d2l\lib\site-packages\wandb\sdk\lib\retry.py", line 131, in __call__
    result = self._call_fn(*args, **kwargs)
  File "C:\Users\MSI\miniconda3\envs\d2l\lib\site-packages\wandb\sdk\internal\internal_api.py", line 2028, in upload_file
    raise _e.with_traceback(sys.exc_info()[2])
  File "C:\Users\MSI\miniconda3\envs\d2l\lib\site-packages\wandb\sdk\internal\internal_api.py", line 1999, in upload_file
    response = self._upload_file_session.put(
  File "C:\Users\MSI\miniconda3\envs\d2l\lib\site-packages\requests\sessions.py", line 647, in put
    return self.request("PUT", url, data=data, **kwargs)
  File "C:\Users\MSI\miniconda3\envs\d2l\lib\site-packages\requests\sessions.py", line 587, in request
    resp = self.send(prep, **send_kwargs)
  File "C:\Users\MSI\miniconda3\envs\d2l\lib\site-packages\requests\sessions.py", line 701, in send
    r = adapter.send(request, **kwargs)
  File "C:\Users\MSI\miniconda3\envs\d2l\lib\site-packages\requests\adapters.py", line 563, in send
    raise SSLError(e, request=request)
wandb.sdk.lib.retry.TransientError: None
2023-04-05 22:03:13,976 DEBUG   HandlerThread:35292 [handler.py:handle_request():144] handle_request: status_report
2023-04-05 22:03:14,236 INFO    Thread-13 :35292 [dir_watcher.py:_on_file_modified():292] file/dir modified: D:\Projects\PFedTrans\system\wandb\run-20230405_220307-yaze6r8c\files\output.log
2023-04-05 22:03:15,821 DEBUG   HandlerThread:35292 [handler.py:handle_request():144] handle_request: partial_history
2023-04-05 22:03:15,821 DEBUG   SenderThread:35292 [sender.py:send():336] send: history
2023-04-05 22:03:15,822 DEBUG   SenderThread:35292 [sender.py:send_request():363] send_request: summary_record
2023-04-05 22:03:15,822 INFO    SenderThread:35292 [sender.py:_save_file():1321] saving file wandb-summary.json with policy end
2023-04-05 22:03:16,258 INFO    Thread-13 :35292 [dir_watcher.py:_on_file_modified():292] file/dir modified: D:\Projects\PFedTrans\system\wandb\run-20230405_220307-yaze6r8c\files\output.log
2023-04-05 22:03:16,258 INFO    Thread-13 :35292 [dir_watcher.py:_on_file_modified():292] file/dir modified: D:\Projects\PFedTrans\system\wandb\run-20230405_220307-yaze6r8c\files\wandb-summary.json
2023-04-05 22:03:17,882 ERROR   wandb-upload_0:35292 [internal_api.py:upload_file():2004] upload_file exception https://storage.googleapis.com/wandb-production.appspot.com/gerid/fedtrans_exp/yaze6r8c/wandb-metadata.json?Expires=1680789789&GoogleAccessId=wandb-production%40appspot.gserviceaccount.com&Signature=BEedncaVomZ5Ufc466jFWDJw9qSr0JGLnX17KARu9PmsraH72jepv6CwMpkW12GtezNux%2BzRLxshycUnNmo6gdWg7jtnf%2BaMu9Ng3zfSkRMqdLfltBMEak71t90u2%2BGjp6i9hlKks6JF3jmM2jyUWce1Ux%2BvQ%2FKvPcPgXr7zUa1RTrtQU6JYSpCwSPxGecgslAAN30fkn2GDfC6VT%2B9VTe7xkY8k4wTk7dq1ztoaqRJO23ZksffAA2PuuoyLdpEwbs16RF0eS%2F6GNpl29UbIlMy3xi6X0sT%2FZQRNmBcl7tEUrCYqnAyqbB7Vn2P%2FTXZjrRRjDomHGt8aUNPjMa142A%3D%3D: HTTPSConnectionPool(host='storage.googleapis.com', port=443): Max retries exceeded with url: /wandb-production.appspot.com/gerid/fedtrans_exp/yaze6r8c/wandb-metadata.json?Expires=1680789789&GoogleAccessId=wandb-production%40appspot.gserviceaccount.com&Signature=BEedncaVomZ5Ufc466jFWDJw9qSr0JGLnX17KARu9PmsraH72jepv6CwMpkW12GtezNux%2BzRLxshycUnNmo6gdWg7jtnf%2BaMu9Ng3zfSkRMqdLfltBMEak71t90u2%2BGjp6i9hlKks6JF3jmM2jyUWce1Ux%2BvQ%2FKvPcPgXr7zUa1RTrtQU6JYSpCwSPxGecgslAAN30fkn2GDfC6VT%2B9VTe7xkY8k4wTk7dq1ztoaqRJO23ZksffAA2PuuoyLdpEwbs16RF0eS%2F6GNpl29UbIlMy3xi6X0sT%2FZQRNmBcl7tEUrCYqnAyqbB7Vn2P%2FTXZjrRRjDomHGt8aUNPjMa142A%3D%3D (Caused by SSLError(SSLEOFError(8, 'EOF occurred in violation of protocol (_ssl.c:1131)')))
2023-04-05 22:03:17,882 ERROR   wandb-upload_0:35292 [internal_api.py:upload_file():2006] upload_file request headers: {'User-Agent': 'python-requests/2.28.2', 'Accept-Encoding': 'gzip, deflate, br', 'Accept': '*/*', 'Connection': 'keep-alive', 'Content-Length': '1525'}
2023-04-05 22:03:17,882 ERROR   wandb-upload_0:35292 [internal_api.py:upload_file():2008] upload_file response body: 
2023-04-05 22:03:18,285 INFO    Thread-13 :35292 [dir_watcher.py:_on_file_modified():292] file/dir modified: D:\Projects\PFedTrans\system\wandb\run-20230405_220307-yaze6r8c\files\output.log
2023-04-05 22:03:18,741 DEBUG   HandlerThread:35292 [handler.py:handle_request():144] handle_request: partial_history
2023-04-05 22:03:18,741 DEBUG   SenderThread:35292 [sender.py:send():336] send: history
2023-04-05 22:03:18,741 DEBUG   SenderThread:35292 [sender.py:send_request():363] send_request: summary_record
2023-04-05 22:03:18,742 INFO    SenderThread:35292 [sender.py:_save_file():1321] saving file wandb-summary.json with policy end
2023-04-05 22:03:19,294 INFO    Thread-13 :35292 [dir_watcher.py:_on_file_modified():292] file/dir modified: D:\Projects\PFedTrans\system\wandb\run-20230405_220307-yaze6r8c\files\wandb-summary.json
2023-04-05 22:03:19,751 DEBUG   HandlerThread:35292 [handler.py:handle_request():144] handle_request: status_report
2023-04-05 22:03:20,306 INFO    Thread-13 :35292 [dir_watcher.py:_on_file_modified():292] file/dir modified: D:\Projects\PFedTrans\system\wandb\run-20230405_220307-yaze6r8c\files\output.log
2023-04-05 22:03:22,332 INFO    Thread-13 :35292 [dir_watcher.py:_on_file_modified():292] file/dir modified: D:\Projects\PFedTrans\system\wandb\run-20230405_220307-yaze6r8c\files\output.log
2023-04-05 22:03:23,403 ERROR   cpu       :35292 [interfaces.py:monitor():129] Failed to sample metric: process no longer exists (pid=44572)
2023-04-05 22:03:23,412 ERROR   cpu       :35292 [interfaces.py:monitor():129] Failed to sample metric: process no longer exists (pid=44572)
2023-04-05 22:03:23,462 ERROR   memory    :35292 [interfaces.py:monitor():129] Failed to sample metric: process no longer exists (pid=44572)
2023-04-05 22:03:23,463 ERROR   memory    :35292 [interfaces.py:monitor():129] Failed to sample metric: process no longer exists (pid=44572)
2023-04-05 22:03:25,062 DEBUG   HandlerThread:35292 [handler.py:handle_request():144] handle_request: status_report
2023-04-05 22:03:25,151 WARNING StreamThr :35292 [internal.py:is_dead():415] Internal process exiting, parent pid 44572 disappeared
2023-04-05 22:03:25,151 ERROR   StreamThr :35292 [internal.py:wandb_internal():153] Internal process shutdown.
2023-04-05 22:03:25,416 ERROR   cpu       :35292 [interfaces.py:monitor():129] Failed to sample metric: process no longer exists (pid=44572)
2023-04-05 22:03:25,424 ERROR   cpu       :35292 [interfaces.py:monitor():129] Failed to sample metric: process no longer exists (pid=44572)
2023-04-05 22:03:25,490 ERROR   memory    :35292 [interfaces.py:monitor():129] Failed to sample metric: process no longer exists (pid=44572)
2023-04-05 22:03:25,490 ERROR   memory    :35292 [interfaces.py:monitor():129] Failed to sample metric: process no longer exists (pid=44572)
2023-04-05 22:03:26,077 INFO    HandlerThread:35292 [handler.py:finish():841] shutting down handler
2023-04-05 22:03:26,077 INFO    SenderThread:35292 [sender.py:finish():1493] shutting down sender
2023-04-05 22:03:26,077 INFO    WriterThread:35292 [datastore.py:close():299] close: D:\Projects\PFedTrans\system\wandb\run-20230405_220307-yaze6r8c\run-yaze6r8c.wandb
2023-04-05 22:03:26,875 ERROR   wandb-upload_0:35292 [internal_api.py:upload_file():2004] upload_file exception https://storage.googleapis.com/wandb-production.appspot.com/gerid/fedtrans_exp/yaze6r8c/wandb-metadata.json?Expires=1680789789&GoogleAccessId=wandb-production%40appspot.gserviceaccount.com&Signature=BEedncaVomZ5Ufc466jFWDJw9qSr0JGLnX17KARu9PmsraH72jepv6CwMpkW12GtezNux%2BzRLxshycUnNmo6gdWg7jtnf%2BaMu9Ng3zfSkRMqdLfltBMEak71t90u2%2BGjp6i9hlKks6JF3jmM2jyUWce1Ux%2BvQ%2FKvPcPgXr7zUa1RTrtQU6JYSpCwSPxGecgslAAN30fkn2GDfC6VT%2B9VTe7xkY8k4wTk7dq1ztoaqRJO23ZksffAA2PuuoyLdpEwbs16RF0eS%2F6GNpl29UbIlMy3xi6X0sT%2FZQRNmBcl7tEUrCYqnAyqbB7Vn2P%2FTXZjrRRjDomHGt8aUNPjMa142A%3D%3D: HTTPSConnectionPool(host='storage.googleapis.com', port=443): Max retries exceeded with url: /wandb-production.appspot.com/gerid/fedtrans_exp/yaze6r8c/wandb-metadata.json?Expires=1680789789&GoogleAccessId=wandb-production%40appspot.gserviceaccount.com&Signature=BEedncaVomZ5Ufc466jFWDJw9qSr0JGLnX17KARu9PmsraH72jepv6CwMpkW12GtezNux%2BzRLxshycUnNmo6gdWg7jtnf%2BaMu9Ng3zfSkRMqdLfltBMEak71t90u2%2BGjp6i9hlKks6JF3jmM2jyUWce1Ux%2BvQ%2FKvPcPgXr7zUa1RTrtQU6JYSpCwSPxGecgslAAN30fkn2GDfC6VT%2B9VTe7xkY8k4wTk7dq1ztoaqRJO23ZksffAA2PuuoyLdpEwbs16RF0eS%2F6GNpl29UbIlMy3xi6X0sT%2FZQRNmBcl7tEUrCYqnAyqbB7Vn2P%2FTXZjrRRjDomHGt8aUNPjMa142A%3D%3D (Caused by SSLError(SSLEOFError(8, 'EOF occurred in violation of protocol (_ssl.c:1131)')))
2023-04-05 22:03:26,875 ERROR   wandb-upload_0:35292 [internal_api.py:upload_file():2006] upload_file request headers: {'User-Agent': 'python-requests/2.28.2', 'Accept-Encoding': 'gzip, deflate, br', 'Accept': '*/*', 'Connection': 'keep-alive', 'Content-Length': '1525'}
2023-04-05 22:03:26,875 ERROR   wandb-upload_0:35292 [internal_api.py:upload_file():2008] upload_file response body: 
2023-04-05 22:03:27,425 ERROR   cpu       :35292 [interfaces.py:monitor():129] Failed to sample metric: process no longer exists (pid=44572)
2023-04-05 22:03:27,447 ERROR   cpu       :35292 [interfaces.py:monitor():129] Failed to sample metric: process no longer exists (pid=44572)
2023-04-05 22:03:27,516 ERROR   memory    :35292 [interfaces.py:monitor():129] Failed to sample metric: process no longer exists (pid=44572)
2023-04-05 22:03:27,516 ERROR   memory    :35292 [interfaces.py:monitor():129] Failed to sample metric: process no longer exists (pid=44572)
2023-04-05 22:03:28,052 INFO    SenderThread:35292 [dir_watcher.py:finish():362] shutting down directory watcher
2023-04-05 22:03:28,389 INFO    SenderThread:35292 [dir_watcher.py:_on_file_modified():292] file/dir modified: D:\Projects\PFedTrans\system\wandb\run-20230405_220307-yaze6r8c\files\output.log
2023-04-05 22:03:28,390 INFO    SenderThread:35292 [dir_watcher.py:finish():392] scan: D:\Projects\PFedTrans\system\wandb\run-20230405_220307-yaze6r8c\files
2023-04-05 22:03:28,390 INFO    SenderThread:35292 [dir_watcher.py:finish():406] scan save: D:\Projects\PFedTrans\system\wandb\run-20230405_220307-yaze6r8c\files\conda-environment.yaml conda-environment.yaml
2023-04-05 22:03:28,391 INFO    SenderThread:35292 [dir_watcher.py:finish():406] scan save: D:\Projects\PFedTrans\system\wandb\run-20230405_220307-yaze6r8c\files\config.yaml config.yaml
2023-04-05 22:03:28,391 INFO    SenderThread:35292 [dir_watcher.py:finish():406] scan save: D:\Projects\PFedTrans\system\wandb\run-20230405_220307-yaze6r8c\files\output.log output.log
2023-04-05 22:03:28,392 INFO    SenderThread:35292 [dir_watcher.py:finish():406] scan save: D:\Projects\PFedTrans\system\wandb\run-20230405_220307-yaze6r8c\files\requirements.txt requirements.txt
2023-04-05 22:03:28,392 INFO    SenderThread:35292 [dir_watcher.py:finish():406] scan save: D:\Projects\PFedTrans\system\wandb\run-20230405_220307-yaze6r8c\files\wandb-metadata.json wandb-metadata.json
2023-04-05 22:03:28,392 INFO    SenderThread:35292 [dir_watcher.py:finish():406] scan save: D:\Projects\PFedTrans\system\wandb\run-20230405_220307-yaze6r8c\files\wandb-summary.json wandb-summary.json
2023-04-05 22:03:28,393 INFO    SenderThread:35292 [file_pusher.py:finish():162] shutting down file pusher
2023-04-05 22:03:28,393 INFO    SenderThread:35292 [file_pusher.py:join():167] waiting for file pusher
