2023-04-05 20:33:02,822 INFO    StreamThr :21724 [internal.py:wandb_internal():87] W&B internal server running at pid: 21724, started at: 2023-04-05 20:33:02.821695
2023-04-05 20:33:02,822 DEBUG   HandlerThread:21724 [handler.py:handle_request():144] handle_request: status
2023-04-05 20:33:02,823 INFO    WriterThread:21724 [datastore.py:open_for_write():85] open: D:\Projects\PFedTrans\system\wandb\run-20230405_203302-i65resk1\run-i65resk1.wandb
2023-04-05 20:33:02,827 DEBUG   SenderThread:21724 [sender.py:send():336] send: header
2023-04-05 20:33:02,827 DEBUG   SenderThread:21724 [sender.py:send():336] send: run
2023-04-05 20:33:06,406 INFO    SenderThread:21724 [retry.py:__call__():172] Retry attempt failed:
Traceback (most recent call last):
  File "C:\Users\MSI\miniconda3\envs\d2l\lib\site-packages\urllib3\connectionpool.py", line 700, in urlopen
    self._prepare_proxy(conn)
  File "C:\Users\MSI\miniconda3\envs\d2l\lib\site-packages\urllib3\connectionpool.py", line 996, in _prepare_proxy
    conn.connect()
  File "C:\Users\MSI\miniconda3\envs\d2l\lib\site-packages\urllib3\connection.py", line 364, in connect
    self.sock = conn = self._connect_tls_proxy(hostname, conn)
  File "C:\Users\MSI\miniconda3\envs\d2l\lib\site-packages\urllib3\connection.py", line 499, in _connect_tls_proxy
    socket = ssl_wrap_socket(
  File "C:\Users\MSI\miniconda3\envs\d2l\lib\site-packages\urllib3\util\ssl_.py", line 453, in ssl_wrap_socket
    ssl_sock = _ssl_wrap_socket_impl(sock, context, tls_in_tls)
  File "C:\Users\MSI\miniconda3\envs\d2l\lib\site-packages\urllib3\util\ssl_.py", line 495, in _ssl_wrap_socket_impl
    return ssl_context.wrap_socket(sock)
  File "C:\Users\MSI\miniconda3\envs\d2l\lib\ssl.py", line 500, in wrap_socket
    return self.sslsocket_class._create(
  File "C:\Users\MSI\miniconda3\envs\d2l\lib\ssl.py", line 1040, in _create
    self.do_handshake()
  File "C:\Users\MSI\miniconda3\envs\d2l\lib\ssl.py", line 1309, in do_handshake
    self._sslobj.do_handshake()
ssl.SSLEOFError: EOF occurred in violation of protocol (_ssl.c:1131)

During handling of the above exception, another exception occurred:

Traceback (most recent call last):
  File "C:\Users\MSI\miniconda3\envs\d2l\lib\site-packages\requests\adapters.py", line 489, in send
    resp = conn.urlopen(
  File "C:\Users\MSI\miniconda3\envs\d2l\lib\site-packages\urllib3\connectionpool.py", line 787, in urlopen
    retries = retries.increment(
  File "C:\Users\MSI\miniconda3\envs\d2l\lib\site-packages\urllib3\util\retry.py", line 592, in increment
    raise MaxRetryError(_pool, url, error or ResponseError(cause))
urllib3.exceptions.MaxRetryError: HTTPSConnectionPool(host='api.wandb.ai', port=443): Max retries exceeded with url: /graphql (Caused by SSLError(SSLEOFError(8, 'EOF occurred in violation of protocol (_ssl.c:1131)')))

During handling of the above exception, another exception occurred:

Traceback (most recent call last):
  File "C:\Users\MSI\miniconda3\envs\d2l\lib\site-packages\wandb\sdk\lib\retry.py", line 131, in __call__
    result = self._call_fn(*args, **kwargs)
  File "C:\Users\MSI\miniconda3\envs\d2l\lib\site-packages\wandb\sdk\internal\internal_api.py", line 242, in execute
    return self.client.execute(*args, **kwargs)  # type: ignore
  File "C:\Users\MSI\miniconda3\envs\d2l\lib\site-packages\wandb\vendor\gql-0.2.0\wandb_gql\client.py", line 52, in execute
    result = self._get_result(document, *args, **kwargs)
  File "C:\Users\MSI\miniconda3\envs\d2l\lib\site-packages\wandb\vendor\gql-0.2.0\wandb_gql\client.py", line 60, in _get_result
    return self.transport.execute(document, *args, **kwargs)
  File "C:\Users\MSI\miniconda3\envs\d2l\lib\site-packages\wandb\vendor\gql-0.2.0\wandb_gql\transport\requests.py", line 38, in execute
    request = requests.post(self.url, **post_args)
  File "C:\Users\MSI\miniconda3\envs\d2l\lib\site-packages\requests\api.py", line 115, in post
    return request("post", url, data=data, json=json, **kwargs)
  File "C:\Users\MSI\miniconda3\envs\d2l\lib\site-packages\requests\api.py", line 59, in request
    return session.request(method=method, url=url, **kwargs)
  File "C:\Users\MSI\miniconda3\envs\d2l\lib\site-packages\requests\sessions.py", line 587, in request
    resp = self.send(prep, **send_kwargs)
  File "C:\Users\MSI\miniconda3\envs\d2l\lib\site-packages\requests\sessions.py", line 701, in send
    r = adapter.send(request, **kwargs)
  File "C:\Users\MSI\miniconda3\envs\d2l\lib\site-packages\requests\adapters.py", line 563, in send
    raise SSLError(e, request=request)
requests.exceptions.SSLError: HTTPSConnectionPool(host='api.wandb.ai', port=443): Max retries exceeded with url: /graphql (Caused by SSLError(SSLEOFError(8, 'EOF occurred in violation of protocol (_ssl.c:1131)')))
2023-04-05 20:33:07,833 DEBUG   HandlerThread:21724 [handler.py:handle_request():144] handle_request: keepalive
2023-04-05 20:33:12,878 DEBUG   HandlerThread:21724 [handler.py:handle_request():144] handle_request: keepalive
2023-04-05 20:33:17,914 DEBUG   HandlerThread:21724 [handler.py:handle_request():144] handle_request: keepalive
2023-04-05 20:33:22,958 DEBUG   HandlerThread:21724 [handler.py:handle_request():144] handle_request: keepalive
2023-04-05 20:33:28,011 DEBUG   HandlerThread:21724 [handler.py:handle_request():144] handle_request: keepalive
2023-04-05 20:33:33,044 DEBUG   HandlerThread:21724 [handler.py:handle_request():144] handle_request: keepalive
2023-04-05 20:33:38,082 DEBUG   HandlerThread:21724 [handler.py:handle_request():144] handle_request: keepalive
2023-04-05 20:33:43,127 DEBUG   HandlerThread:21724 [handler.py:handle_request():144] handle_request: keepalive
2023-04-05 20:33:48,163 DEBUG   HandlerThread:21724 [handler.py:handle_request():144] handle_request: keepalive
2023-04-05 20:33:53,195 DEBUG   HandlerThread:21724 [handler.py:handle_request():144] handle_request: keepalive
2023-04-05 20:33:58,232 DEBUG   HandlerThread:21724 [handler.py:handle_request():144] handle_request: keepalive
2023-04-05 20:34:03,301 DEBUG   HandlerThread:21724 [handler.py:handle_request():144] handle_request: cancel
2023-04-05 20:34:03,301 DEBUG   SenderThread:21724 [sender.py:send():345] Record cancelled: run
2023-04-05 20:34:03,301 DEBUG   HandlerThread:21724 [handler.py:handle_request():144] handle_request: cancel
2023-04-05 20:34:03,302 DEBUG   HandlerThread:21724 [handler.py:handle_request():144] handle_request: status_report
2023-04-05 20:34:07,319 INFO    MainThread:21724 [internal.py:handle_exit():77] Internal process exited
